Workbook

Sheet Lookups
A1: Field | B1: Allowed values (one per row) | C1: Definition
A2: SourceType | B2: Legislation
B3: Regulation
B4: Policy
B5: Judicial Case
B6: Administrative Decision
B7: Soft Law
B8: Guidance
A10: Status | B10: In force
B11: Repealed
B12: Pending
B13: Proposed
A15: Level | B15: International
B16: Regional
B17: National
B18: Subnational
A20: ActivityType | B20: Production
B21: Financing
B22: Supply-chain management
B23: Trade
B24: Investment
B25: Service provision
B26: Other
A28: ValueChainPosition | B28: Upstream
B29: Midstream
B30: Downstream
B31: Cross-cutting
A33: GeoScope | B33: Domestic
B34: Transnational
B35: Global
A37: EnvDomain | B37: Climate
B38: Biodiversity
B39: Water
B40: Land
B41: Pollution
B42: Ecosystems
B43: Other
A45: ImpactNature | B45: Direct
B46: Indirect
B47: Induced | C47: Indirect environmental effects that occur because a project triggers additional development or activities (e.g., a new highway leading to urban expansion and increased pollution)
...

Sheet README
A1: Database Workbook: Corporate Activities ↔ Environmental & Social Impacts (Legal Sources)
A2: Workflow: Populate the four entity tables, then link them in the Linkage tab using IDs.
A3: ID formats (suggested): LS-0001, ACT-0001, ENV-0001, SOC-0001, LNK-0001.
A4: StrengthFlag_0_3: 0=no meaningful link; 1=weak/implicit; 2=moderate; 3=strong/explicit.
A5: Knowledge Translation fields capture how scientific knowledge enters law (models, indicators, experts, reports).

Sheet Legal_Source
A1: LegalSourceID | B1: Jurisdiction | C1: Level | D1: Database | E1: SourceType | F1: Title/CaseName | G1: Citation/CaseNumber | H1: Year | I1: Status | J1: Decision/Enactment Date | K1: Court/Body/Agency | L1: URL | M1: Short Summary | N1: Keywords/Tags | O1: Researcher Notes | P1: Could extended case note be relevant?
A2: LS-0001 | B2: EU; Sweden; India | C2: Select (state level, country), (country), (regional or internatinal court) | D2: Westlaw/ LexisNexis/ heinOnline/ Jstor/ | E2: Select | F2: Full title | G2: Official citation/case no. | H2: YYYY | I2: Select | J2: YYYY-MM-DD | K2: Court/regulator | L2: Stable link | M2: 1–3 sentences | N2: comma-separated
A3: LS-0001 | B3: United Kingdom | C3: National (Supreme Court) | D3: UK SC Website | E3: Judicial Decision | F3: R (Finch on behalf of the Weald Action Group & Others) v Surrey County Council & Others | G3: UKSC/2022/0064 | H3: 2024 | I3: Decided | J3: 20th June 2024 | K3: UK Supreme Court | L3: https://www.supremecourt.uk/cases/uksc-2022-0064 | M3: The UK Supreme Court held that an Environmental Impact Assessment for an oil extraction project must assess downstream greenhouse gas emissions resulting from the combustion of the extracted oil. The failure to consider these foreseeable climate impacts rendered the planning permission unlawful.
A4: LS-0002 | B4: Norway | C4: National (Supreme Court) | D4: The Greenpeace | E4: Judicial Decision | F4: Greenpeace Nordic Association and Others v. Ministry of Petroleum and Energy | G4: HR-2020-2472-P | H4: 2020 | I4: Decided | J4: 43853 | K4: Supreme Court of Norway (Høyesterett). | L4: https://www.greenpeace.org/static/planet4-norway-stateless/2022/05/d38444b5-annexes.pdf | M4: Environmental organizations challenged Norway’s decision to grant oil and gas exploration licenses in the Barents Sea, arguing that it violated the constitutional right to a healthy environment (Article 112 of the Norwegian Constitution). The Supreme Court upheld the licenses, finding that the government had not exceeded its discretion, and did not require full assessment of downstream (exported) emissions.
A5: LS-0003 | B5: Australia | C5: National (Supreme Court) | D5: Supreme Court of Victoria website | E5: Judicial Decision | F5: Environment Victoria Inc v. AGL Loy Yang Pty Ltd & Ors. | G5: [2022] VSC 814 | H5: 2022 | I5: Decided | J5: 44916 | K5: Supreme Court of Victoria at Melbourne | L5: https://www.supremecourt.vic.gov.au/sites/default/files/2022-12/Environment%20Victoria%20v%20AGL%20Loy%20Yang%20%5B2022%5D%20VSC%20814.pdf | M5: Environment Victoria brought proceedings against AGL alleging that its climate and net-zero statements were misleading because the company continued operating major coal-fired power stations such as Loy Yang A. The case challenges the accuracy of AGL’s public climate commitments and raises issues of corporate accountability for ongoing fossil fuel production.
A6: LS-0004 | B6: Poland | C6: National | D6: Columbia Law School, The Climate Litigation Database | E6: Judicial Decision | F6: ClientEarth v. Polska Grupa Energetyczna | G6: XXIV GC 94/22 ( Not the final citation) | H6: 2019 (Filing date) | I6: Pending | J6: - | K6: Commercial Court – Warsaw | L6: https://www.climatecasechart.com/document/clientearth-v-polska-grupa-energetyczna_cdf4 | M6: ClientEarth, as a shareholder of Polska Grupa Energetyczna (PGE), filed a lawsuit in the Warsaw Commercial Court alleging that the company’s continued investment in and operation of coal-fired power plants violates directors’ duties and exposes the company to foreseeable climate transition and financial risks. The claim argues that PGE’s corporate strategy is inconsistent with Poland’s climate commitments and EU law and could harm shareholders by locking in fossil fuel dependency. The case is still pending, with substantive arguments focusing on corporate governance obligations in the context of climate risk.
A7: LS-0005 | B7: US | C7: State Level | D7: PepsiCo Website | E7: Judicial Decision | F7: Commissioner of the Department of Licensing and Consumer Affairs v. PepsiCo, Inc. | G7: This case currently exists as a filed complaint in the Virgin Islands Superior Court (docket SX‑2025‑CV‑00102) and has been removed to the U.S. District Court for the District of the Virgin Islands as civil action 1:25‑cv‑00024. No published reporter citation is yet available. | H7: 2023 (Filing Date) | I7: Pending | J7: - | K7: District Court of the Virgin Islands | L7: https://investors.pepsico.com/docs/pepsico-5v9wci20/media/Files/investors/q2-2025-form-10q.pdf (Page 50) | M7: The District of Columbia sued PepsiCo under consumer protection law, alleging that the company materially contributed to plastic pollution in the District and misled consumers regarding the recyclability and environmental sustainability of its products. The case seeks to hold PepsiCo accountable for its role in single-use plastic waste and related environmental harm.
A8: LS-0006 | B8: United States (Montana) | C8: State Level | D8: Western Environmental law Website | E8: Judicial Decision | F8: Held v. Montana | G8: CDV-2020-307 | H8: 2023 | I8: Decided | J8: 14th August 2023 | K8: Supreme Court Of The State Of Montana | L8: https://westernlaw.org/wp-content/uploads/2023/08/2023.08.14-Held-v.-Montana-victory-order.pdf | M8: Youth plaintiffs challenged Montana’s limitation on considering greenhouse gas emissions in environmental reviews, arguing it violated their constitutional right to a clean and healthful environment. The court held that the state’s prohibition on considering climate impacts was unconstitutional and that climate change harms the plaintiffs’ constitutional rights.
A9: LS-0007 | B9: Belgium First instance trial court (lowest level civil court in Belgium) | C9: National Level | D9: Columbia Law School, The Climate Litigation Database | E9: Judicil decision | F9: ClientEarth v NBB | G9: There is no official case citation because the case was dismissed at first instance and the appeal was subsequently withdrawn. | H9: 2022 | I9: Withdrawn in late 2022 following policy changes by the ECB | J9: Dismissed Dec. 2021; withdrawn Nov. 29, 2022). | K9: Brussels Court of First Instance | L9: https://www.climatecasechart.com/document/clientearth-v-belgian-national-bank_6797 | M9: ClientEarth v. Belgian National Bank (NBB) was a national Belgian case filed in April 2021 in the Brussels Court of First Instance. The lawsuit challenged the NBB’s corporate bond purchases under the ECB’s quantitative easing programme for failing to account for climate and environmental obligations. The court dismissed the case in December 2021, and the appeal was withdrawn in late 2022 after the ECB updated its policy to include climate-related considerations in the Corporate Sector Purchase Programme (CSPP), so the case has no published judgment or official citation.
A10: LS-0008 | B10: Switzerland | C10: Regional level | D10: ENNHRI | E10: Judicial Decision | F10: Klimaseniorinnen Schweiz and Others v Switzerland | G10: App. No. 53600/20; [2024] ECHR 304 | H10: 2024 | I10: Decided | J10: 45391 | K10: European Court of Human Rights | L10: https://ennhri.org/wp-content/uploads/2022/12/ENNHRI-3rd-party-intervention-_Klimaseniorinnen-v.-Switzerland.pdf | M10: The European Court of Human Rights held that Switzerland violated Articles 8 and 6 of the European Convention on Human Rights by failing to implement an adequate regulatory framework to mitigate climate change. The Court found that insufficient national climate action exposed applicants, elderly women particularly vulnerable to heatwaves to serious climate-related risks. It recognised a state duty to adopt and effectively implement measures aligned with climate science and emissions reduction pathways.
A11: LS-0009 | B11: United States–Canada Arbitration | C11: International | D11: REPORTS OF INTERNATIONAL ARBITRAL AWARDS | E11: Arbitrl Award | F11: Trail Smelter Arbitration | G11: 3 R.I.A.A. 1905 | H11: 1941 | I11: Decided | J11: 1938 (interim award), 1941 (final award) | K11: Arbitral Tribunal constituted under the 1935 Convention between the U.S. and Canada | L11: https://legal.un.org/riaa/cases/vol_iii/1905-1982.pdf | M11: The Trail Smelter case (U.S. v. Canada, 1938/1941) arose when a Canadian smelter in Trail, British Columbia, emitted sulfur dioxide fumes that damaged crops and forests in Washington State, USA. The dispute established that a state is responsible for transboundary environmental harm originating within its territory. The arbitral tribunal ruled Canada liable for damages and set a landmark principle in international law: “no state has the right to use or permit the use of its territory in such a way as to cause injury to another state.”
A12: LS-0010 | B12: Netherlands | C12: National (District Court – The Hague) | D12: Rechtspraak.nl | E12: Judicial Decision | F12: Milieudefensie et al. v Royal Dutch Shell plc | G12: C/09/571932 / HA ZA 19-379 | H12: 2021 | I12: Decided | J12: 26th May 2021 | K12: District Court of The Hague | L12: https://uitspraken.rechtspraak.nl/details?id=ECLI:NL:RBDHA:2021:5339 | M12: The Hague District Court ordered Royal Dutch Shell to reduce its global CO₂ emissions by 45% by 2030 (relative to 2019 levels), holding that Shell has an independent duty of care under Dutch law to align its corporate policy with the goals of the Paris Agreement. The ruling extended responsibility to Shell’s entire value chain, including Scope 3 emissions.
A13: LS-0011 | B13: Fance | C13: National (Judicial Court – Paris) | D13: Columbia Law School, The Climate Litigation Database | E13: Judicial Decision | F13: Ville de Paris and Others v. TotalEnergies SE | H13: 2023 (Filing Date) | I13: Pending | J13: - | K13: Tribunal judiciaire de Paris | L13: https://blogs.law.columbia.edu/climatechange/2025/12/16/greenwashing-on-trial-the-paris-tribunal-finds-totalenergies-misled-consumers-with-its-carbon-neutrality-claims/#:~:text=Introduction,the%20international%20climate%20litigation%20landscape. | M13: The City of Paris and environmental organisations brought proceedings against TotalEnergies under France’s Duty of Vigilance Law, alleging that the company’s climate strategy and continued hydrocarbon production are inconsistent with the Paris Agreement’s 1.5°C objective. The claim argues that TotalEnergies must reduce not only direct emissions (Scopes 1 and 2) but also indirect value-chain emissions (Scope 3). The case tests whether corporate due diligence obligations extend to systemic climate impacts.
A14: LS-0012 | B14: United Kingdom | C14: National (UK Supreme Court) | D14: Supreme Court of the United Kingdom | E14: Judicial Decision | F14: Vedanta Resources plc v Lungowe | G14: [2019] UKSC 20 | H14: 2019 | I14: Decided | J14: 10th of April 2019 | K14: UK Supreme Court | L14: https://www.supremecourt.uk/cases/uksc-2017-0185 | M14: The UK Supreme Court held that a UK parent company, Vedanta Resources plc, could owe a duty of care for environmental harm caused by its Zambian subsidiary. The Court found it arguable that Vedanta exercised sufficient control and oversight over the subsidiary’s operations to establish potential liability. The decision confirmed jurisdiction of English courts and significantly advanced transnational corporate environmental accountability.
A15: LS-0013 | B15: United Kingdom | C15: National (UK Supreme Court) | D15: Supreme Court of the United Kingdom | E15: Judicial Decision | F15: Okpabi v Royal Dutch Shell plc | G15: [2021] UKSC 3 | H15: 2021 | I15: Decided | J15: 12th February 2021 | K15: UK Supreme Court | L15: https://www.supremecourt.uk/cases/uksc-2018-0068 | M15: The UK Supreme Court held that it was arguable that the UK-based parent company, Royal Dutch Shell plc, owed a duty of care for environmental damage allegedly caused by its Nigerian subsidiary. The Court clarified that parent company liability depends on the degree of control and oversight exercised over subsidiary operations, not on formal corporate separation alone. The ruling significantly strengthened transnational corporate environmental accountability in supply-chain and group-structure contexts.
A16: LS-0014 | F16: United States – Import Prohibition of Certain Shrimp and Shrimp Products (Shrimp–Turtle Case)
A17: LS-0015 | F17: European Communities – Measures Prohibiting the Importation and Marketing of Seal Products

Sheet Corporate_Activity
A1: ActivityID | B1: Sector/Industry | C1: Type of Corporate Activity | D1: Position in Value Chain | E1: Actors Covered | F1: Geographic Scope of Activity | G1: Company/Entity Name (if relevant) | H1: Project/Site/Asset (if relevant) | I1: Transnational Elements (if any) | J1: Keywords/Tags | K1: Researcher Notes
A2: ACT-0001 | B2: finance; mining | C2: Select | D2: Select | E2: multinationals; FIs | F2: Select | G2: Optional | H2: Optional | I2: Optional | J2: comma-separated

Sheet Environmental_Impact
A1: EnvImpactID | B1: Environmental Domain | C1: Type of Impact | D1: Nature of Impact | E1: Temporal Horizon | F1: Impact Location | G1: Indicators/Models Mentioned | H1: Scientific Basis Referenced (Y/N) | I1: Severity/Scale (qual) | J1: Keywords/Tags | K1: Researcher Notes
A2: ENV-0001 | B2: Select | C2: emissions; habitat loss | D2: Select | E2: Select | F2: Place | G2: Models/indicators | H2: Y/N | I2: Low/Med/High + note | J2: comma-separated

Sheet Social_Human_Impact
A1: SocialImpactID | B1: Affected Groups | C1: Type of Social Impact | D1: Rights/Interests Implicated | E1: Vulnerability Considerations | F1: Impact Location | G1: Severity/Scale (qual) | H1: Keywords/Tags | I1: Researcher Notes
A2: SOC-0001 | B2: Workers; Indigenous peoples | C2: health; livelihoods | D2: right to health | E2: Gender/Indigenous/etc. | F2: Place | G2: Low/Med/High + note | H2: comma-separated

Sheet Linkage
A1: LinkID | B1: LegalSourceID | C1: LegalSource Check | D1: ActivityID | E1: Activity Check | F1: EnvImpactID | G1: EnvImpact Check | H1: SocialImpactID | I1: SocialImpact Check | J1: Link Explicitness | K1: Causation Standard | L1: Evidentiary Threshold | M1: Burden of Proof | N1: Core Legal Issue | O1: Legal Basis (statute/treaty/constitutional/case law) | P1: Interpretive Approach | Q1: Treatment of Scientific Uncertainty | R1: Obligations Imposed (type) | S1: Enforcement Mechanism | T1: Sanctions/Remedies | U1: Access to Remedy | V1: Materiality Framing | W1: Time Horizon of Materiality | X1: Integration with Corporate Governance | Y1: Precedent Value | Z1: Systemic Significance (free text) | AA1: Interaction with Other Frameworks (free text) | AB1: StrengthFlag_0_3 | AC1: Knowledge Translation (narrative) | AD1: KnowledgeTranslationType | AE1: Additional Notes
A2: LNK-0001 | B2: LS-0001 | C2: Auto | D2: ACT-0001 | E2: Auto | F2: ENV-0001 | G2: Auto | H2: SOC-0001 | I2: Auto | J2: Select | K2: Select | L2: Select | M2: Select | N2: liability; due diligence; disclosure | O2: Free text | P2: Select | Q2: Select | R2: Select | S2: Select | T2: Free text | U2: Select | V2: Select | W2: Short/Medium/Long | X2: Board duties/risk mgmt/internal controls | Y2: Select | Z2: Free text | AA2: Free text | AB2: 0–3 | AC2: Free text | AD2: Select
C3: =IF(B3="","",IF(COUNTIF(Legal_Source!$A$3:$A$123,B3)>0,"OK","MISSING")) | E3: =IF(D3="","",IF(COUNTIF(Corporate_Activity!$A$3:$A$123,D3)>0,"OK","MISSING")) | G3: =IF(F3="","",IF(COUNTIF(Environmental_Impact!$A$3:$A$123,F3)>0,"OK","MISSING")) | I3: =IF(H3="","",IF(COUNTIF(Social_Human_Impact!$A$3:$A$123,H3)>0,"OK","MISSING"))
C4: =IF(B4="","",IF(COUNTIF(Legal_Source!$A$3:$A$123,B4)>0,"OK","MISSING")) | E4: =IF(D4="","",IF(COUNTIF(Corporate_Activity!$A$3:$A$123,D4)>0,"OK","MISSING")) | G4: =IF(F4="","",IF(COUNTIF(Environmental_Impact!$A$3:$A$123,F4)>0,"OK","MISSING")) | I4: =IF(H4="","",IF(COUNTIF(Social_Human_Impact!$A$3:$A$123,H4)>0,"OK","MISSING"))
C5: =IF(B5="","",IF(COUNTIF(Legal_Source!$A$3:$A$123,B5)>0,"OK","MISSING")) | E5: =IF(D5="","",IF(COUNTIF(Corporate_Activity!$A$3:$A$123,D5)>0,"OK","MISSING")) | G5: =IF(F5="","",IF(COUNTIF(Environmental_Impact!$A$3:$A$123,F5)>0,"OK","MISSING")) | I5: =IF(H5="","",IF(COUNTIF(Social_Human_Impact!$A$3:$A$123,H5)>0,"OK","MISSING"))
C6: =IF(B6="","",IF(COUNTIF(Legal_Source!$A$3:$A$123,B6)>0,"OK","MISSING")) | E6: =IF(D6="","",IF(COUNTIF(Corporate_Activity!$A$3:$A$123,D6)>0,"OK","MISSING")) | G6: =IF(F6="","",IF(COUNTIF(Environmental_Impact!$A$3:$A$123,F6)>0,"OK","MISSING")) | I6: =IF(H6="","",IF(COUNTIF(Social_Human_Impact!$A$3:$A$123,H6)>0,"OK","MISSING"))
C7: =IF(B7="","",IF(COUNTIF(Legal_Source!$A$3:$A$123,B7)>0,"OK","MISSING")) | E7: =IF(D7="","",IF(COUNTIF(Corporate_Activity!$A$3:$A$123,D7)>0,"OK","MISSING")) | G7: =IF(F7="","",IF(COUNTIF(Environmental_Impact!$A$3:$A$123,F7)>0,"OK","MISSING")) | I7: =IF(H7="","",IF(COUNTIF(Social_Human_Impact!$A$3:$A$123,H7)>0,"OK","MISSING"))
C8: =IF(B8="","",IF(COUNTIF(Legal_Source!$A$3:$A$123,B8)>0,"OK","MISSING")) | E8: =IF(D8="","",IF(COUNTIF(Corporate_Activity!$A$3:$A$123,D8)>0,"OK","MISSING")) | G8: =IF(F8="","",IF(COUNTIF(Environmental_Impact!$A$3:$A$123,F8)>0,"OK","MISSING")) | I8: =IF(H8="","",IF(COUNTIF(Social_Human_Impact!$A$3:$A$123,H8)>0,"OK","MISSING"))
C9: =IF(B9="","",IF(COUNTIF(Legal_Source!$A$3:$A$123,B9)>0,"OK","MISSING")) | E9: =IF(D9="","",IF(COUNTIF(Corporate_Activity!$A$3:$A$123,D9)>0,"OK","MISSING")) | G9: =IF(F9="","",IF(COUNTIF(Environmental_Impact!$A$3:$A$123,F9)>0,"OK","MISSING")) | I9: =IF(H9="","",IF(COUNTIF(Social_Human_Impact!$A$3:$A$123,H9)>0,"OK","MISSING"))
C10: =IF(B10="","",IF(COUNTIF(Legal_Source!$A$3:$A$123,B10)>0,"OK","MISSING")) | E10: =IF(D10="","",IF(COUNTIF(Corporate_Activity!$A$3:$A$123,D10)>0,"OK","MISSING")) | G10: =IF(F10="","",IF(COUNTIF(Environmental_Impact!$A$3:$A$123,F10)>0,"OK","MISSING")) | I10: =IF(H10="","",IF(COUNTIF(Social_Human_Impact!$A$3:$A$123,H10)>0,"OK","MISSING"))
C11: =IF(B11="","",IF(COUNTIF(Legal_Source!$A$3:$A$123,B11)>0,"OK","MISSING")) | E11: =IF(D11="","",IF(COUNTIF(Corporate_Activity!$A$3:$A$123,D11)>0,"OK","MISSING")) | G11: =IF(F11="","",IF(COUNTIF(Environmental_Impact!$A$3:$A$123,F11)>0,"OK","MISSING")) | I11: =IF(H11="","",IF(COUNTIF(Social_Human_Impact!$A$3:$A$123,H11)>0,"OK","MISSING"))
C12: =IF(B12="","",IF(COUNTIF(Legal_Source!$A$3:$A$123,B12)>0,"OK","MISSING")) | E12: =IF(D12="","",IF(COUNTIF(Corporate_Activity!$A$3:$A$123,D12)>0,"OK","MISSING")) | G12: =IF(F12="","",IF(COUNTIF(Environmental_Impact!$A$3:$A$123,F12)>0,"OK","MISSING")) | I12: =IF(H12="","",IF(COUNTIF(Social_Human_Impact!$A$3:$A$123,H12)>0,"OK","MISSING"))
C13: =IF(B13="","",IF(COUNTIF(Legal_Source!$A$3:$A$123,B13)>0,"OK","MISSING")) | E13: =IF(D13="","",IF(COUNTIF(Corporate_Activity!$A$3:$A$123,D13)>0,"OK","MISSING")) | G13: =IF(F13="","",IF(COUNTIF(Environmental_Impact!$A$3:$A$123,F13)>0,"OK","MISSING")) | I13: =IF(H13="","",IF(COUNTIF(Social_Human_Impact!$A$3:$A$123,H13)>0,"OK","MISSING"))
C14: =IF(B14="","",IF(COUNTIF(Legal_Source!$A$3:$A$123,B14)>0,"OK","MISSING")) | E14: =IF(D14="","",IF(COUNTIF(Corporate_Activity!$A$3:$A$123,D14)>0,"OK","MISSING")) | G14: =IF(F14="","",IF(COUNTIF(Environmental_Impact!$A$3:$A$123,F14)>0,"OK","MISSING")) | I14: =IF(H14="","",IF(COUNTIF(Social_Human_Impact!$A$3:$A$123,H14)>0,"OK","MISSING"))
... C123: =IF(B123="","",IF(COUNTIF(Legal_Source!$A$3:$A$123,B123)>0,"OK","MISSING")) | E123: =IF(D123="","",IF(COUNTIF(Corporate_Activity!$A$3:$A$123,D123)>0,"OK","MISSING")) | G123: =IF(F123="","",IF(COUNTIF(Environmental_Impact!$A$3:$A$123,F123)>0,"OK","MISSING")) | I123: =IF(H123="","",IF(COUNTIF(Social_Human_Impact!$A$3:$A$123,H123)>0,"OK","MISSING"))
